Workbook

Sheet Scenario
A1: scenairo_number | B1: Scenario 1 | C1: Scenario 2 | D1: Scenario 3 | E1: Scenario 4 | F1: Scenario 5 | G1: Scenario 6 | H1: Scenario 7 | I1: Scenario 8 | J1: Scenario 9 | K1: Scenario 10 | L1: Scenario 11 | M1: Scenario 12 | N1: Scenario 13 | O1: Scenario 14
A2: scenario_name | B2: =B6 -> default | C2: =C6 -> no-landuse-change | D2: =D6 -> low-uptake | E2: =E6 -> low-tech-change | F2: =F6 -> farm-plan-only | G2: =G6 -> all-profit-farmers | H2: =H6 -> all-enviro-farmers | I2: =I6 -> high-tech-change | ... K2: =K6 -> high-debt | L2: n/a | M2: n/a | N2: n/a | O2: n/a
A3: run-seed | B3: 1 | C3: 1 | D3: 1 | E3: 1 | F3: 1 | G3: 1 | H3: 1 | I3: 1 | J3: 1 | K3: 1
A4: geography-seed | B4: 0 | C4: 0 | D4: 0 | E4: 0 | F4: 0 | G4: 0 | H4: 0 | I4: 0 | J4: 0 | K4: 0
A5: output_data_folder | B5: C:\Users\adam.daigneault\Documents\GitHub\moving-the-middle-abm\data\output | C5: C:\Users\adam.daigneault\Documents\GitHub\moving-the-middle-abm\data\output | D5: C:\Users\adam.daigneault\Documents\GitHub\moving-the-middle-abm\data\output | E5: C:\Users\adam.daigneault\Documents\GitHub\moving-the-middle-abm\data\output | F5: C:\Users\adam.daigneault\Documents\GitHub\moving-the-middle-abm\data\output | G5: C:\Users\adam.daigneault\Documents\GitHub\moving-the-middle-abm\data\output | H5: C:\Users\adam.daigneault\Documents\GitHub\moving-the-middle-abm\data\output | I5: C:\Users\adam.daigneault\Documents\GitHub\moving-the-middle-abm\data\output | J5: C:\Users\adam.daigneault\Documents\GitHub\moving-the-middle-abm\data\output | K5: C:\Users\adam.daigneault\Documents\GitHub\moving-the-middle-abm\data\output
A6: market_data_folder | B6: default | C6: no-landuse-change | D6: low-uptake | E6: low-tech-change | F6: farm-plan-only | G6: all-profit-farmers | H6: all-enviro-farmers | I6: high-tech-change | J6: low-init-intervention | K6: high-debt
A7: spatial_data_folder | B7: C:\Users\adam.daigneault\Documents\GitHub\moving-the-middle-abm\data\spatial\Waihou-Piako | C7: C:\Users\adam.daigneault\Documents\GitHub\moving-the-middle-abm\data\spatial\Waihou-Piako | D7: C:\Users\adam.daigneault\Documents\GitHub\moving-the-middle-abm\data\spatial\Waihou-Piako | E7: C:\Users\adam.daigneault\Documents\GitHub\moving-the-middle-abm\data\spatial\Waihou-Piako | F7: C:\Users\adam.daigneault\Documents\GitHub\moving-the-middle-abm\data\spatial\Waihou-Piako | G7: C:\Users\adam.daigneault\Documents\GitHub\moving-the-middle-abm\data\spatial\Waihou-Piako | H7: C:\Users\adam.daigneault\Documents\GitHub\moving-the-middle-abm\data\spatial\Waihou-Piako | I7: C:\Users\adam.daigneault\Documents\GitHub\moving-the-middle-abm\data\spatial\Waihou-Piako | J7: C:\Users\adam.daigneault\Documents\GitHub\moving-the-middle-abm\data\spatial\Waihou-Piako | K7: C:\Users\adam.daigneault\Documents\GitHub\moving-the-middle-abm\data\spatial\Waihou-Piako
A8: geography_from_files | B8: TRUE | C8: TRUE | D8: TRUE | E8: TRUE | F8: TRUE | G8: TRUE | H8: TRUE | I8: TRUE | J8: TRUE | K8: TRUE
A9: scenario | B9: default | C9: no-landuse-change | D9: low-uptake | E9: low-tech-change | F9: farm-plan-only | G9: all-profit-farmers | H9: all-enviro-farmers | I9: high-tech-change | J9: low-init-intervention | K9: high-debt
A10: region | B10: Waihou-Piako | C10: Waihou-Piako | D10: Waihou-Piako | E10: Waihou-Piako | F10: Waihou-Piako | G10: Waihou-Piako | H10: Waihou-Piako | I10: Waihou-Piako | J10: Waihou-Piako | K10: Waihou-Piako
A11: LUC_aggregation_steps | B11: 0 | C11: 0 | D11: 0 | E11: 0 | F11: 0 | G11: 0 | H11: 0 | I11: 0 | J11: 0 | K11: 0
A12: number_of_farms | B12: 0 | C12: 0 | D12: 0 | E12: 0 | F12: 0 | G12: 0 | H12: 0 | I12: 0 | J12: 0 | K12: 0
A13: correlated_landuse | B13: 0 | C13: 0 | D13: 0 | E13: 0 | F13: 0 | G13: 0 | H13: 0 | I13: 0 | J13: 0 | K13: 0
A14: landuse_aggregation_steps | B14: 0 | C14: 0 | D14: 0 | E14: 0 | F14: 0 | G14: 0 | H14: 0 | I14: 0 | J14: 0 | K14: 0
A15: include_networks | B15: FALSE | C15: FALSE | D15: FALSE | E15: FALSE | F15: FALSE | G15: FALSE | H15: FALSE | I15: FALSE | J15: FALSE | K15: FALSE
A16: n_local_links | B16: 6 | C16: 6 | D16: 6 | E16: 6 | F16: 6 | G16: 6 | H16: 6 | I16: 6 | J16: 6 | K16: 6
A17: n_catchment_links | B17: 6 | C17: 6 | D17: 6 | E17: 6 | F17: 6 | G17: 6 | H17: 6 | I17: 6 | J17: 6 | K17: 6
A18: interest_rate | B18: 3 | C18: 3 | D18: 3 | E18: 3 | F18: 3 | G18: 3 | H18: 3 | I18: 3 | J18: 3 | K18: 10
A19: mortgate_term | B19: 20 | C19: 20 | D19: 20 | E19: 20 | F19: 20 | G19: 20 | H19: 20 | I19: 20 | J19: 20 | K19: 20
A20: nudge_efficacy | B20: 1 | C20: 1 | D20: 1 | E20: 1 | F20: 1 | G20: 1 | H20: 1 | I20: 1 | J20: 1 | K20: 1
A21: landuse_change_on_succession | B21: FALSE | C21: FALSE | D21: FALSE | E21: FALSE | F21: FALSE | G21: FALSE | H21: FALSE | I21: FALSE | J21: FALSE | K21: FALSE
A22: apply_suitability | B22: TRUE | C22: TRUE | D22: TRUE | E22: TRUE | F22: TRUE | G22: TRUE | H22: TRUE | I22: TRUE | J22: TRUE | K22: TRUE

Sheet Estimates
A1: Catchment | B1: Scenario | C1: tick | D1: income_costs_income | E1: income_costs_costs | F1: income_costs_debt | G1: interventions_Build_Wetland | H1: interventions_Clean_Races | I1: interventions_Farm_Plan | J1: interventions_Riparian_Planting | K1: intervention_limits_Build_Wetland | L1: intervention_limits_Clean_Races | M1: intervention_limits_Farm_Plan | N1: intervention_limits_Riparian_Planting | O1: intervention_props_Build_Wetland | P1: intervention_props_Clean_Races | Q1: intervention_props_Farm_Plan | R1: intervention_props_Riparian_Planting | S1: landuse_Crop | T1: landuse_Dairy | U1: landuse_Forest | V1: landuse_SNB | W1: env_metrics_ghg_emissions | X1: env_metrics_nitrates | Y1: env_metrics_sediment | Z1: env_metrics_phosphates | AA1: env_metrics_e_coli | AB1: income_costs_netrev
A2: =Scenario!B10 -> Waihou-Piako | B2: =Scenario!B2 -> default | C2: 0 | D2: 1414664765 | E2: 1196543938 | F2: 413244508 | G2: 1332 | H2: 840 | I2: 1219 | J2: 1267 | K2: 12351 | L2: 9078 | M2: 12167 | N2: 12351 | O2: 0.1078 | P2: 0.0925 | Q2: 0.1002 | R2: 0.1026 | S2: 184 | T2: 9078 | U2: 1068 | V2: 3089 | W2: 1379504.3 | X2: 5738137.5 | Y2: 1133321.2 | Z2: 133573.86 | AA2: 724425.82 | AB2: =D2-E2 -> 218120827
A3: =A2 -> Waihou-Piako | B3: =B2 -> default | C3: 1 | D3: 1414355374 | E3: 1195580426 | F3: 539290032 | G3: 1857 | H3: 1299 | I3: 1744 | J3: 1805 | K3: 11986 | L3: 8732 | M3: 11780 | N3: 11986 | O3: 0.1549 | P3: 0.1488 | Q3: 0.148 | R3: 0.1506 | S3: 206 | T3: 8732 | U3: 1433 | V3: 3048 | W3: 1379442.7 | X3: 5738698.1 | Y3: 1133888.9 | Z3: 133519.22 | AA3: 724125.34 | AB3: =D3-E3 -> 218774948
A4: =A3 -> Waihou-Piako | B4: =B3 -> default | C4: 2 | D4: 1388621652 | E4: 1176412327 | F4: 516275058 | G4: 2300 | H4: 1619 | I4: 2265 | J4: 2329 | K4: 11701 | L4: 8480 | M4: 11448 | N4: 11701 | O4: 0.1966 | P4: 0.1909 | Q4: 0.1979 | R4: 0.199 | S4: 253 | T4: 8480 | U4: 1718 | V4: 2968 | W4: 1232595.2 | X4: 5371382.7 | Y4: 1021632.7 | Z4: 122403.34 | AA4: 646410.77 | AB4: =D4-E4 -> 212209325
A5: =A4 -> Waihou-Piako | B5: =B4 -> default | C5: 3 | D5: 1371598906 | E5: 1165610145 | F5: 435703211 | G5: 2792 | H5: 2053 | I5: 2849 | J5: 2805 | K5: 11456 | L5: 8237 | M5: 11171 | N5: 11456 | O5: 0.2437 | P5: 0.2492 | Q5: 0.255 | R5: 0.2448 | S5: 285 | T5: 8237 | U5: 1963 | V5: 2934 | W5: 1122346.1 | X5: 5077642.8 | Y5: 910980.58 | Z5: 113206.3 | AA5: 584418.83 | AB5: =D5-E5 -> 205988761
A6: =A5 -> Waihou-Piako | B6: =B5 -> default | C6: 4 | D6: 1352155262 | E6: 1151264464 | F6: 392852800 | G6: 3180 | H6: 2387 | I6: 3408 | J6: 3261 | K6: 11270 | L6: 8086 | M6: 10974 | N6: 11270 | O6: 0.2822 | P6: 0.2952 | Q6: 0.3106 | R6: 0.2894 | S6: 296 | T6: 8086 | U6: 2149 | V6: 2888 | W6: 1019124.1 | X6: 4778034.4 | Y6: 813920.61 | Z6: 103720.03 | AA6: 522956.67 | AB6: =D6-E6 -> 200890798
A7: =A6 -> Waihou-Piako | B7: =B6 -> default | C7: 5 | D7: 1342620321 | E7: 1144498439 | F7: 374964916 | G7: 3687 | H7: 2702 | I7: 3931 | J7: 3753 | K7: 11133 | L7: 7954 | M7: 10839 | N7: 11133 | O7: 0.3312 | P7: 0.3397 | Q7: 0.3627 | R7: 0.3371 | S7: 294 | T7: 7954 | U7: 2286 | V7: 2885 | W7: 943355.44 | X7: 4547126.5 | Y7: 738094.83 | Z7: 96836.4 | AA7: 477983.46 | AB7: =D7-E7 -> 198121882
A8: =A7 -> Waihou-Piako | B8: =B7 -> default | C8: 6 | D8: 1329591747 | E8: 1137944185 | F8: 364740154 | G8: 4198 | H8: 2986 | I8: 4305 | J8: 4189 | K8: 10951 | L8: 7778 | M8: 10649 | N8: 10951 | O8: 0.3833 | P8: 0.3839 | Q8: 0.4043 | R8: 0.3825 | S8: 302 | T8: 7778 | U8: 2468 | V8: 2871 | W8: 887153.86 | X8: 4308107.8 | Y8: 665648.98 | Z8: 89467.808 | AA8: 433742.45 | AB8: =D8-E8 -> 191647562
A9: =A8 -> Waihou-Piako | B9: =B8 -> default | C9: 7 | D9: 1312680754 | E9: 1125545689 | F9: 370093649 | G9: 4512 | H9: 3305 | I9: 4675 | J9: 4482 | K9: 10795 | L9: 7632 | M9: 10491 | N9: 10795 | O9: 0.418 | P9: 0.433 | Q9: 0.4456 | R9: 0.4152 | S9: 304 | T9: 7632 | U9: 2624 | V9: 2859 | W9: 805372.56 | X9: 4071737.1 | Y9: 598523.82 | Z9: 82686.496 | AA9: 388602.86 | AB9: =D9-E9 -> 187135065
A10: =A9 -> Waihou-Piako | B10: =B9 -> default | C10: 8 | D10: 1302238124 | E10: 1117826234 | F10: 366746915 | G10: 4921 | H10: 3577 | I10: 4989 | J10: 4866 | K10: 10660 | L10: 7524 | M10: 10363 | N10: 10660 | O10: 0.4616 | P10: 0.4754 | Q10: 0.4814 | R10: 0.4565 | S10: 297 | T10: 7524 | U10: 2759 | V10: 2839 | W10: 745304.75 | X10: 3912447.7 | Y10: 552595.89 | Z10: 78092.784 | AA10: 357283.07 | AB10: =D10-E10 -> 184411890
A11: =A10 -> Waihou-Piako | B11: =B10 -> default | C11: 9 | D11: 1292494805 | E11: 1111216713 | F11: 364069497 | G11: 5218 | H11: 3818 | I11: 5326 | J11: 5075 | K11: 10494 | L11: 7381 | M11: 10189 | N11: 10494 | O11: 0.4972 | P11: 0.5173 | Q11: 0.5227 | R11: 0.4836 | S11: 305 | T11: 7381 | U11: 2925 | V11: 2808 | W11: 691212.05 | X11: 3726600 | Y11: 514233.81 | Z11: 73097.632 | AA11: 326050.86 | AB11: =D11-E11 -> 181278092
A12: =A11 -> Waihou-Piako | B12: =B11 -> default | C12: 10 | D12: 1282157445 | E12: 1103811554 | F12: 357796201 | G12: 5519 | H12: 4043 | I12: 5685 | J12: 5327 | K12: 10354 | L12: 7285 | M12: 10040 | N12: 10354 | O12: 0.533 | P12: 0.555 | Q12: 0.5662 | R12: 0.5145 | S12: 314 | T12: 7285 | U12: 3065 | V12: 2755 | W12: 625571.47 | X12: 3580957.1 | Y12: 483296.13 | Z12: 69351.536 | AA12: 303426.56 | AB12: =D12-E12 -> 178345891
A13: =A12 -> Waihou-Piako | B13: =Scenario!C2 -> no-landuse-change | C13: 0 | D13: 1414664765 | E13: 1196543938 | F13: 413244508 | G13: 1332 | H13: 840 | I13: 1219 | J13: 1267 | K13: 12351 | L13: 9078 | M13: 12167 | N13: 12351 | O13: 0.1078 | P13: 0.0925 | Q13: 0.1002 | R13: 0.1026 | S13: 184 | T13: 9078 | U13: 1068 | V13: 3089 | W13: 1379504.3 | X13: 5738137.5 | Y13: 1133321.2 | Z13: 133573.86 | AA13: 724425.82 | AB13: =D13-E13 -> 218120827
A14: =A13 -> Waihou-Piako | B14: =B13 -> no-landuse-change | C14: 1 | D14: 1414355374 | E14: 1195580426 | F14: 536940147 | G14: 1941 | H14: 1172 | I14: 1923 | J14: 1854 | K14: 12351 | L14: 9078 | M14: 12167 | N14: 12351 | O14: 0.1572 | P14: 0.1291 | Q14: 0.1581 | R14: 0.1501 | S14: 184 | T14: 9078 | U14: 1068 | V14: 3089 | W14: 1379442.7 | X14: 5738698.1 | Y14: 1133888.9 | Z14: 133519.22 | AA14: 724125.34 | AB14: =D14-E14 -> 218774948
A15: =A14 -> Waihou-Piako | B15: =B14 -> no-landuse-change | C15: 2 | D15: 1410369197 | E15: 1196314744 | F15: 517770605 | G15: 2566 | H15: 1593 | I15: 2516 | J15: 2499 | K15: 12351 | L15: 9078 | M15: 12167 | N15: 12351 | O15: 0.2078 | P15: 0.1755 | Q15: 0.2068 | R15: 0.2023 | S15: 184 | T15: 9078 | U15: 1068 | V15: 3089 | W15: 1367148.8 | X15: 5561784 | Y15: 1004919.1 | Z15: 125040.67 | AA15: 667592.26 | AB15: =D15-E15 -> 214054453
A16: =A15 -> Waihou-Piako | B16: =B15 -> no-landuse-change | C16: 3 | D16: 1406305686 | E16: 1196783663 | F16: 473057366 | G16: 3243 | H16: 2005 | I16: 3146 | J16: 3038 | K16: 12351 | L16: 9078 | M16: 12167 | N16: 12351 | O16: 0.2626 | P16: 0.2209 | Q16: 0.2586 | R16: 0.246 | S16: 184 | T16: 9078 | U16: 1068 | V16: 3089 | W16: 1354394.8 | X16: 5354652.3 | Y16: 889758.26 | Z16: 116355.52 | AA16: 610442.78 | AB16: =D16-E16 -> 209522023
A17: =A16 -> Waihou-Piako | B17: =B16 -> no-landuse-change | C17: 4 | D17: 1402000135 | E17: 1196623380 | F17: 438342584 | G17: 3826 | H17: 2400 | I17: 3764 | J17: 3604 | K17: 12351 | L17: 9078 | M17: 12167 | N17: 12351 | O17: 0.3098 | P17: 0.2644 | Q17: 0.3094 | R17: 0.2918 | S17: 184 | T17: 9078 | U17: 1068 | V17: 3089 | W17: 1341486.8 | X17: 5170557.6 | Y17: 795226.8 | Z17: 108322.13 | AA17: 559349.36 | AB17: =D17-E17 -> 205376755
A18: =A17 -> Waihou-Piako | B18: =B17 -> no-landuse-change | C18: 5 | D18: 1400591435 | E18: 1197077131 | F18: 392532844 | G18: 4353 | H18: 2972 | I18: 4306 | J18: 4115 | K18: 12351 | L18: 9078 | M18: 12167 | N18: 12351 | O18: 0.3524 | P18: 0.3274 | Q18: 0.3539 | R18: 0.3332 | S18: 184 | T18: 9078 | U18: 1068 | V18: 3089 | W18: 1329725.3 | X18: 4989080.1 | Y18: 705336.69 | Z18: 101554.32 | AA18: 515503.17 | AB18: =D18-E18 -> 203514304
A19: =A18 -> Waihou-Piako | B19: =B18 -> no-landuse-change | C19: 6 | D19: 1396089949 | E19: 1197739477 | F19: 403608080 | G19: 4950 | H19: 3326 | I19: 4867 | J19: 4604 | K19: 12351 | L19: 9078 | M19: 12167 | N19: 12351 | O19: 0.4008 | P19: 0.3664 | Q19: 0.4 | R19: 0.3728 | S19: 184 | T19: 9078 | U19: 1068 | V19: 3089 | W19: 1323381.8 | X19: 4825034.8 | Y19: 636046.19 | Z19: 95088.544 | AA19: 471360.8 | AB19: =D19-E19 -> 198350472
A20: =A19 -> Waihou-Piako | B20: =B19 -> no-landuse-change | C20: 7 | D20: 1393250787 | E20: 1197403841 | F20: 410049848 | G20: 5343 | H20: 3656 | I20: 5389 | J20: 5012 | K20: 12351 | L20: 9078 | M20: 12167 | N20: 12351 | O20: 0.4326 | P20: 0.4027 | Q20: 0.4429 | R20: 0.4058 | S20: 184 | T20: 9078 | U20: 1068 | V20: 3089 | W20: 1310079.2 | X20: 4664597.8 | Y20: 565463.6 | Z20: 89001.136 | AA20: 433904.82 | AB20: =D20-E20 -> 195846946
A21: =A20 -> Waihou-Piako | B21: =B20 -> no-landuse-change | C21: 8 | D21: 1391423752 | E21: 1197494504 | F21: 379786464 | G21: 5849 | H21: 3973 | I21: 5965 | J21: 5448 | K21: 12351 | L21: 9078 | M21: 12167 | N21: 12351 | O21: 0.4736 | P21: 0.4377 | Q21: 0.4903 | R21: 0.4411 | S21: 184 | T21: 9078 | U21: 1068 | V21: 3089 | W21: 1302645.4 | X21: 4552543 | Y21: 519727.41 | Z21: 84647.136 | AA21: 405919.52 | AB21: =D21-E21 -> 193929248
A22: =A21 -> Waihou-Piako | B22: =B21 -> no-landuse-change | C22: 9 | D22: 1388112081 | E22: 1196856501 | F22: 375749440 | G22: 6180 | H22: 4316 | I22: 6674 | J22: 5916 | K22: 12351 | L22: 9078 | M22: 12167 | N22: 12351 | O22: 0.5004 | P22: 0.4754 | Q22: 0.5485 | R22: 0.479 | S22: 184 | T22: 9078 | U22: 1068 | V22: 3089 | W22: 1292043.6 | X22: 4414408.9 | Y22: 465896.51 | Z22: 79699.104 | AA22: 375574.77 | AB22: =D22-E22 -> 191255580
A23: =A22 -> Waihou-Piako | B23: =B22 -> no-landuse-change | C23: 10 | D23: 1385439615 | E23: 1196595248 | F23: 408307573 | G23: 6556 | H23: 4604 | I23: 7105 | J23: 6296 | K23: 12351 | L23: 9078 | M23: 12167 | N23: 12351 | O23: 0.5308 | P23: 0.5072 | Q23: 0.584 | R23: 0.5098 | S23: 184 | T23: 9078 | U23: 1068 | V23: 3089 | W23: 1285793.7 | X23: 4292131.4 | Y23: 408541.1 | Z23: 75557.472 | AA23: 350834.27 | AB23: =D23-E23 -> 188844367
A24: =A23 -> Waihou-Piako | B24: =Scenario!D2 -> low-uptake | C24: 0 | D24: 1414664765 | E24: 1196543938 | F24: 413244508 | G24: 1332 | H24: 840 | I24: 1219 | J24: 1267 | K24: 12351 | L24: 9078 | M24: 12167 | N24: 12351 | O24: 0.1078 | P24: 0.0925 | Q24: 0.1002 | R24: 0.1026 | S24: 184 | T24: 9078 | U24: 1068 | V24: 3089 | W24: 1379504.3 | X24: 5738137.5 | Y24: 1133321.2 | Z24: 133573.86 | AA24: 724425.82 | AB24: =D24-E24 -> 218120827
A25: =A24 -> Waihou-Piako | B25: =B24 -> low-uptake | C25: 1 | D25: 1414355374 | E25: 1195580426 | F25: 560348737 | G25: 1533 | H25: 983 | I25: 1398 | J25: 1443 | K25: 12194 | L25: 8941 | M25: 12007 | N25: 12194 | O25: 0.1257 | P25: 0.1099 | Q25: 0.1164 | R25: 0.1183 | S25: 187 | T25: 8941 | U25: 1225 | V25: 3066 | W25: 1379442.7 | X25: 5738698.1 | Y25: 1133888.9 | Z25: 133519.22 | AA25: 724125.34 | AB25: =D25-E25 -> 218774948
A26: =A25 -> Waihou-Piako | B26: =B25 -> low-uptake | C26: 2 | D26: 1405022734 | E26: 1188948964 | F26: 544045213 | G26: 1745 | H26: 1124 | I26: 1591 | J26: 1634 | K26: 12030 | L26: 8788 | M26: 11830 | N26: 12030 | O26: 0.1451 | P26: 0.1279 | Q26: 0.1345 | R26: 0.1358 | S26: 200 | T26: 8788 | U26: 1389 | V26: 3042 | W26: 1318198.5 | X26: 5604322.5 | Y26: 1090810.2 | Z26: 129350.34 | AA26: 695826.53 | AB26: =D26-E26 -> 216073770
A27: =A26 -> Waihou-Piako | B27: =B26 -> low-uptake | C27: 3 | D27: 1394058213 | E27: 1181752817 | F27: 524108733 | G27: 1896 | H27: 1240 | I27: 1774 | J27: 1764 | K27: 11853 | L27: 8643 | M27: 11639 | N27: 11853 | O27: 0.16 | P27: 0.1435 | Q27: 0.1524 | R27: 0.1488 | S27: 214 | T27: 8643 | U27: 1566 | V27: 2996 | W27: 1256047.2 | X27: 5452569.8 | Y27: 1041359.3 | Z27: 125067.89 | AA27: 664463.52 | AB27: =D27-E27 -> 212305396
A28: =A27 -> Waihou-Piako | B28: =B27 -> low-uptake | C28: 4 | D28: 1386398241 | E28: 1174718645 | F28: 469381980 | G28: 2086 | H28: 1355 | I28: 1990 | J28: 1939 | K28: 11762 | L28: 8564 | M28: 11538 | N28: 11762 | O28: 0.1774 | P28: 0.1582 | Q28: 0.1725 | R28: 0.1649 | S28: 224 | T28: 8564 | U28: 1657 | V28: 2974 | W28: 1188589.3 | X28: 5326176.8 | Y28: 997150.14 | Z28: 121202.05 | AA28: 638524.48 | AB28: =D28-E28 -> 211679596
A29: =A28 -> Waihou-Piako | B29: =B28 -> low-uptake | C29: 5 | D29: 1378930400 | E29: 1169861189 | F29: 416380375 | G29: 2229 | H29: 1504 | I29: 2218 | J29: 2120 | K29: 11661 | L29: 8445 | M29: 11431 | N29: 11661 | O29: 0.1911 | P29: 0.1781 | Q29: 0.194 | R29: 0.1818 | S29: 230 | T29: 8445 | U29: 1758 | V29: 2986 | W29: 1153623.3 | X29: 5221564.9 | Y29: 959089.62 | Z29: 117846.26 | AA29: 616187.68 | AB29: =D29-E29 -> 209069211
A30: =A29 -> Waihou-Piako | B30: =B29 -> low-uptake | C30: 6 | D30: 1369090377 | E30: 1162110428 | F30: 410131844 | G30: 2426 | H30: 1629 | I30: 2467 | J30: 2312 | K30: 11514 | L30: 8300 | M30: 11277 | N30: 11514 | O30: 0.2107 | P30: 0.1963 | Q30: 0.2188 | R30: 0.2008 | S30: 237 | T30: 8300 | U30: 1905 | V30: 2977 | W30: 1107929.9 | X30: 5109773.4 | Y30: 919724.03 | Z30: 114682.06 | AA30: 593233.01 | AB30: =D30-E30 -> 206979949
A31: =A30 -> Waihou-Piako | B31: =B30 -> low-uptake | C31: 7 | D31: 1357772881 | E31: 1154322191 | F31: 413244130 | G31: 2586 | H31: 1755 | I31: 2607 | J31: 2492 | K31: 11438 | L31: 8213 | M31: 11184 | N31: 11438 | O31: 0.2261 | P31: 0.2137 | Q31: 0.2331 | R31: 0.2179 | S31: 254 | T31: 8213 | U31: 1981 | V31: 2971 | W31: 1046842.9 | X31: 4972523.9 | Y31: 872408.38 | Z31: 110667.68 | AA31: 565699.92 | AB31: =D31-E31 -> 203450690
A32: =A31 -> Waihou-Piako | B32: =B31 -> low-uptake | C32: 8 | D32: 1350909361 | E32: 1148825818 | F32: 431057134 | G32: 2764 | H32: 1847 | I32: 2771 | J32: 2691 | K32: 11354 | L32: 8078 | M32: 11074 | N32: 11354 | O32: 0.2434 | P32: 0.2286 | Q32: 0.2502 | R32: 0.237 | S32: 280 | T32: 8078 | U32: 2065 | V32: 2996 | W32: 1017113.5 | X32: 4884861.8 | Y32: 839703.63 | Z32: 107869.01 | AA32: 547268.05 | AB32: =D32-E32 -> 202083543
A33: =A32 -> Waihou-Piako | B33: =B32 -> low-uptake | C33: 9 | D33: 1339104579 | E33: 1138871314 | F33: 409636864 | G33: 2915 | H33: 1969 | I33: 2925 | J33: 2860 | K33: 11224 | L33: 7984 | M33: 10933 | N33: 11224 | O33: 0.2597 | P33: 0.2466 | Q33: 0.2675 | R33: 0.2548 | S33: 291 | T33: 7984 | U33: 2195 | V33: 2949 | W33: 973686.61 | X33: 4751813.7 | Y33: 811552.72 | Z33: 104218.38 | AA33: 524390.05 | AB33: =D33-E33 -> 200233265
A34: =A33 -> Waihou-Piako | B34: =B33 -> low-uptake | C34: 10 | D34: 1331830243 | E34: 1133958567 | F34: 419009405 | G34: 3062 | H34: 2115 | I34: 3099 | J34: 3041 | K34: 11178 | L34: 7931 | M34: 10878 | N34: 11178 | O34: 0.2739 | P34: 0.2667 | Q34: 0.2849 | R34: 0.2721 | S34: 300 | T34: 7931 | U34: 2241 | V34: 2947 | W34: 928033.41 | X34: 4640285.7 | Y34: 785326.88 | Z34: 101168.85 | AA34: 504572.77 | AB34: =D34-E34 -> 197871676
A35: =A34 -> Waihou-Piako | B35: =Scenario!E2 -> low-tech-change | C35: 0 | D35: 1414664765 | E35: 1196543938 | F35: 413244508 | G35: 1332 | H35: 840 | I35: 1219 | J35: 1267 | K35: 12351 | L35: 9078 | M35: 12167 | N35: 12351 | O35: 0.1078 | P35: 0.0925 | Q35: 0.1002 | R35: 0.1026 | S35: 184 | T35: 9078 | U35: 1068 | V35: 3089 | W35: 1379504.3 | X35: 5738137.5 | Y35: 1133321.2 | Z35: 133573.86 | AA35: 724425.82 | AB35: =D35-E35 -> 218120827
A36: =A35 -> Waihou-Piako | B36: =B35 -> low-tech-change | C36: 1 | D36: 1414355374 | E36: 1195580426 | F36: 539290032 | G36: 1857 | H36: 1299 | I36: 1744 | J36: 1805 | K36: 11986 | L36: 8732 | M36: 11780 | N36: 11986 | O36: 0.1549 | P36: 0.1488 | Q36: 0.148 | R36: 0.1506 | S36: 206 | T36: 8732 | U36: 1433 | V36: 3048 | W36: 1379442.7 | X36: 5738698.1 | Y36: 1133888.9 | Z36: 133519.22 | AA36: 724125.34 | AB36: =D36-E36 -> 218774948
A37: =A36 -> Waihou-Piako | B37: =B36 -> low-tech-change | C37: 2 | D37: 1249731688 | E37: 1176412327 | F37: 368040856 | G37: 2355 | H37: 1568 | I37: 2189 | J37: 2233 | K37: 11723 | L37: 8530 | M37: 11519 | N37: 11723 | O37: 0.2009 | P37: 0.1838 | Q37: 0.19 | R37: 0.1905 | S37: 204 | T37: 8530 | U37: 1696 | V37: 2989 | W37: 1232595.2 | X37: 5371382.7 | Y37: 1021632.7 | Z37: 122403.34 | AA37: 646410.77 | AB37: =D37-E37 -> 73319361
A38: =A37 -> Waihou-Piako | B38: =B37 -> low-tech-change | C38: 3 | D38: 1236678093 | E38: 1167502437 | F38: 268722386 | G38: 2808 | H38: 1839 | I38: 2534 | J38: 2563 | K38: 11243 | L38: 8159 | M38: 11027 | N38: 11243 | O38: 0.2498 | P38: 0.2254 | Q38: 0.2298 | R38: 0.228 | S38: 216 | T38: 8159 | U38: 2176 | V38: 2868 | W38: 1134521.5 | X38: 5104942.6 | Y38: 928105.68 | Z38: 113993.9 | AA38: 589045.98 | AB38: =D38-E38 -> 69175656
A39: =A38 -> Waihou-Piako | B39: =B38 -> low-tech-change | C39: 4 | D39: 1215573501 | E39: 1149478228 | F39: 191482186 | G39: 3258 | H39: 2118 | I39: 2979 | J39: 3009 | K39: 10925 | L39: 7903 | M39: 10683 | N39: 10925 | O39: 0.2982 | P39: 0.268 | Q39: 0.2789 | R39: 0.2754 | S39: 242 | T39: 7903 | U39: 2494 | V39: 2780 | W39: 960019.55 | X39: 4769657 | Y39: 832134.46 | Z39: 104856.51 | AA39: 525622.45 | AB39: =D39-E39 -> 66095273
A40: =A39 -> Waihou-Piako | B40: =B39 -> low-tech-change | C40: 5 | D40: 1200582478 | E40: 1138781608 | F40: 151907575 | G40: 3632 | H40: 2424 | I40: 3551 | J40: 3437 | K40: 10757 | L40: 7770 | M40: 10501 | N40: 10757 | O40: 0.3376 | P40: 0.312 | Q40: 0.3382 | R40: 0.3195 | S40: 256 | T40: 7770 | U40: 2662 | V40: 2731 | W40: 839892.24 | X40: 4474977.1 | Y40: 745728.32 | Z40: 96126.992 | AA40: 469869.89 | AB40: =D40-E40 -> 61800870
...

Sheet Pivot
A3: Sum of env_metrics_ghg_emissions | B3: Column Labels
A4: Row Labels | B4: default | C4: no-landuse-change | D4: low-uptake | E4: low-tech-change | F4: farm-plan-only | G4: all-profit-farmers | H4: all-enviro-farmers | I4: high-tech-change | J4: low-init-intervention | K4: high-debt | L4: Grand Total
A5: 0 | B5: 1379504.3 | C5: 1379504.3 | D5: 1379504.3 | E5: 1379504.3 | F5: 1379504.3 | G5: 1379504.3 | H5: 1379504.3 | I5: 1379504.3 | J5: 1396309.5 | K5: 1379504.3 | L5: 13811848
A6: 1 | B6: 1379442.7 | C6: 1379442.7 | D6: 1379442.7 | E6: 1379442.7 | F6: 1379442.7 | G6: 1379442.7 | H6: 1379442.7 | I6: 1379442.7 | J6: 1396305.4 | K6: 1379442.7 | L6: 13811290
A7: 2 | B7: 1232595.2 | C7: 1367148.8 | D7: 1318198.5 | E7: 1232595.2 | F7: 1243408.8 | G7: 1236302.2 | H7: 1225231.1 | I7: 1232595.2 | J7: 1229435 | K7: 1224353.2 | L7: 12541863
A8: 3 | B8: 1122346.1 | C8: 1354394.8 | D8: 1256047.2 | E8: 1134521.5 | F8: 1107960.7 | G8: 1116589.5 | H8: 1097751.7 | I8: 1164119.1 | J8: 1097386 | K8: 1038216.5 | L8: 11489333
A9: 4 | B9: 1019124.1 | C9: 1341486.8 | D9: 1188589.3 | E9: 960019.55 | F9: 1003403 | G9: 1019234.8 | H9: 999510.22 | I9: 1062449.8 | J9: 999124.21 | K9: 943415.02 | L9: 10536357
A10: 5 | B10: 943355.44 | C10: 1329725.3 | D10: 1153623.3 | E10: 839892.24 | F10: 903656.27 | G10: 941269.7 | H10: 911472.82 | I10: 975790.94 | J10: 920156 | K10: 848928.78 | L10: 9767870.7
A11: 6 | B11: 887153.86 | C11: 1323381.8 | D11: 1107929.9 | E11: 772404.62 | F11: 856034.78 | G11: 852324.5 | H11: 831964.96 | I11: 892580.58 | J11: 850773.06 | K11: 774876.18 | L11: 9149424.3
A12: 7 | B12: 805372.56 | C12: 1310079.2 | D12: 1046842.9 | E12: 679687.14 | F12: 771334.66 | G12: 786825.82 | H12: 758212.05 | I12: 797010.24 | J12: 774307.92 | K12: 698896.14 | L12: 8428568.7
A13: 8 | B13: 745304.75 | C13: 1302645.4 | D13: 1017113.5 | E13: 618902.18 | F13: 715915.66 | G13: 716993.46 | H13: 661491.94 | I13: 727653.15 | J13: 686746.03 | K13: 629958.05 | L13: 7822724.1
A14: 9 | B14: 691212.05 | C14: 1292043.6 | D14: 973686.61 | E14: 563646.82 | F14: 657093.1 | G14: 658835.73 | H14: 594712.22 | I14: 654441.95 | J14: 615222.74 | K14: 557103.14 | L14: 7257998
A15: 10 | B15: 625571.47 | C15: 1285793.7 | D15: 928033.41 | E15: 484916.42 | F15: 580118.06 | G15: 572735.02 | H15: 525871.98 | I15: 607010.61 | J15: 538126.35 | K15: 485150.16 | L15: 6633327.2
